[2022-12-27T00:25:36.815+0000] {taskinstance.py:1087} INFO - Dependencies all met for <TaskInstance: final_project_dag.extract_test scheduled__2022-12-26T00:00:00+00:00 [queued]>
[2022-12-27T00:25:36.846+0000] {taskinstance.py:1087} INFO - Dependencies all met for <TaskInstance: final_project_dag.extract_test scheduled__2022-12-26T00:00:00+00:00 [queued]>
[2022-12-27T00:25:36.851+0000] {taskinstance.py:1283} INFO - 
--------------------------------------------------------------------------------
[2022-12-27T00:25:36.856+0000] {taskinstance.py:1284} INFO - Starting attempt 4 of 6
[2022-12-27T00:25:36.860+0000] {taskinstance.py:1285} INFO - 
--------------------------------------------------------------------------------
[2022-12-27T00:25:36.940+0000] {taskinstance.py:1304} INFO - Executing <Task(PythonOperator): extract_test> on 2022-12-26 00:00:00+00:00
[2022-12-27T00:25:36.960+0000] {standard_task_runner.py:55} INFO - Started process 3001 to run task
[2022-12-27T00:25:36.963+0000] {standard_task_runner.py:82} INFO - Running: ['***', 'tasks', 'run', 'final_project_dag', 'extract_test', 'scheduled__2022-12-26T00:00:00+00:00', '--job-id', '152', '--raw', '--subdir', 'DAGS_FOLDER/final_project_dag.py', '--cfg-path', '/tmp/tmpt588et3k']
[2022-12-27T00:25:36.970+0000] {standard_task_runner.py:83} INFO - Job 152: Subtask extract_test
[2022-12-27T00:25:37.756+0000] {task_command.py:389} INFO - Running <TaskInstance: final_project_dag.extract_test scheduled__2022-12-26T00:00:00+00:00 [running]> on host 3dc0e72111ec
[2022-12-27T00:25:38.076+0000] {taskinstance.py:1513} INFO - Exporting the following env vars:
AIRFLOW_CTX_DAG_OWNER=kelompok 3
AIRFLOW_CTX_DAG_ID=final_project_dag
AIRFLOW_CTX_TASK_ID=extract_test
AIRFLOW_CTX_EXECUTION_DATE=2022-12-26T00:00:00+00:00
AIRFLOW_CTX_TRY_NUMBER=4
AIRFLOW_CTX_DAG_RUN_ID=scheduled__2022-12-26T00:00:00+00:00
[2022-12-27T00:25:38.128+0000] {conn.py:1371} WARNING - DNS lookup failed for broker:9092, exception was [Errno -5] No address associated with hostname. Is your advertised.listeners (called advertised.host.name before Kafka 9) correct and resolvable?
[2022-12-27T00:25:38.129+0000] {conn.py:307} ERROR - DNS lookup failed for broker:9092 (AddressFamily.AF_UNSPEC)
[2022-12-27T00:25:38.130+0000] {conn.py:1049} INFO - Probing node bootstrap-0 broker version
[2022-12-27T00:25:38.137+0000] {conn.py:1371} WARNING - DNS lookup failed for broker:9092, exception was [Errno -5] No address associated with hostname. Is your advertised.listeners (called advertised.host.name before Kafka 9) correct and resolvable?
[2022-12-27T00:25:38.139+0000] {conn.py:307} ERROR - DNS lookup failed for broker:9092 (AddressFamily.AF_UNSPEC)
[2022-12-27T00:25:38.146+0000] {conn.py:1371} WARNING - DNS lookup failed for broker:9092, exception was [Errno -5] No address associated with hostname. Is your advertised.listeners (called advertised.host.name before Kafka 9) correct and resolvable?
[2022-12-27T00:25:38.148+0000] {conn.py:307} ERROR - DNS lookup failed for broker:9092 (AddressFamily.AF_UNSPEC)
[2022-12-27T00:25:38.151+0000] {conn.py:1049} INFO - Probing node bootstrap-0 broker version
[2022-12-27T00:25:38.162+0000] {conn.py:1371} WARNING - DNS lookup failed for broker:9092, exception was [Errno -5] No address associated with hostname. Is your advertised.listeners (called advertised.host.name before Kafka 9) correct and resolvable?
[2022-12-27T00:25:38.166+0000] {conn.py:307} ERROR - DNS lookup failed for broker:9092 (AddressFamily.AF_UNSPEC)
[2022-12-27T00:25:38.171+0000] {taskinstance.py:1772} ERROR - Task failed with exception
Traceback (most recent call last):
  File "/home/airflow/.local/lib/python3.7/site-packages/airflow/operators/python.py", line 175, in execute
    return_value = self.execute_callable()
  File "/home/airflow/.local/lib/python3.7/site-packages/airflow/operators/python.py", line 192, in execute_callable
    return self.python_callable(*self.op_args, **self.op_kwargs)
  File "/opt/airflow/dags/etl.py", line 14, in start_etl
    producer = KafkaProducer(bootstrap_servers=['broker'])
  File "/home/airflow/.local/lib/python3.7/site-packages/kafka/producer/kafka.py", line 381, in __init__
    **self.config)
  File "/home/airflow/.local/lib/python3.7/site-packages/kafka/client_async.py", line 239, in __init__
    self.config['api_version'] = self.check_version(timeout=check_timeout)
  File "/home/airflow/.local/lib/python3.7/site-packages/kafka/client_async.py", line 865, in check_version
    raise Errors.NoBrokersAvailable()
kafka.errors.NoBrokersAvailable: NoBrokersAvailable
[2022-12-27T00:25:38.211+0000] {taskinstance.py:1327} INFO - Marking task as UP_FOR_RETRY. dag_id=final_project_dag, task_id=extract_test, execution_date=20221226T000000, start_date=20221227T002536, end_date=20221227T002538
[2022-12-27T00:25:38.293+0000] {standard_task_runner.py:105} ERROR - Failed to execute job 152 for task extract_test (NoBrokersAvailable; 3001)
[2022-12-27T00:25:38.401+0000] {local_task_job.py:159} INFO - Task exited with return code 1
[2022-12-27T00:25:38.500+0000] {taskinstance.py:2582} INFO - 0 downstream tasks scheduled from follow-on schedule check
